Workbook

Sheet Figuur_2
A2: tab switch_beid_stream year, mi
B4: year
A5: switch_beid_stream | B5: 2011 | C5: 2012 | D5: 2013 | E5: 2014 | F5: 2015 | G5: 2016 | H5: 2017 | I5: 2018 | J5: 2019 | K5: 2020 | L5: 2021 | M5: 2022 | N5: 2023 | O5: 2024 | P5: Total
A7: 0 | B7: 5312403 | C7: 5332636 | D7: 5227666 | E7: 5148045 | F7: 5176431 | G7: 5242988 | H7: 5357774 | I7: 5552592 | J7: 5765717 | K7: 5774589 | L7: 5768373 | M7: 5939225 | N7: 6057991 | O7: 6176598 | P7: 79348131
A8: 1 | B8: 1122938 | C8: 1001650 | D8: 1037592 | E8: 1117965 | F8: 1175544 | G8: 1250017 | H8: 1305975 | I8: 1415003 | J8: 1241338 | K8: 1263509 | L8: 1452932 | M8: 1432567 | N8: 1386164 | O8: 1316475 | P8: 20615960
A9: 3 | B9: 553441 | C9: 547067 | D9: 600495 | E9: 655493 | F9: 687131 | G9: 721197 | H9: 956928 | I9: 744799 | J9: 612489 | K9: 844723 | L9: 853754 | M9: 772596 | N9: 744578 | O9: 704347 | P9: 7445193
A10: 4 | B10: 657018 | C10: 684786 | D10: 643707 | E10: 627534 | F10: 601986 | G10: 581530 | H10: 592127 | I10: 702842 | J10: 758872 | K10: 627967 | L10: 716980 | M10: 772045 | N10: 775060 | O10: 768718 | P10: 7217991
A11: Total | B11: 7645800 | C11: 7566139 | D11: 7509460 | E11: 7549037 | F11: 7641092 | G11: 7795732 | H11: 8212804 | I11: 8415236 | J11: 8378416 | K11: 8510788 | L11: 8792039 | M11: 8916433 | N11: 8963793 | O11: 8966138 | P11: 114627275
A13: LET OP: TBV FIGUUR 2 SBI_NEW, DUS LEES ALS T+1
A15: table sbi_new year if hoofdbaan_new!=., mi row col format(%12.0f)
B17: 2011 | C17: 2012 | D17: 2013 | E17: 2014 | F17: 2015 | G17: 2016 | H17: 2017 | I17: 2018 | J17: 2019 | K17: 2020 | L17: 2021 | M17: 2022 | N17: 2023 | O17: 2024 | P17: Total
A19: 1 | B19: 79947 | C19: 81072 | D19: 80436 | E19: 79710 | F19: 80350 | G19: 80543 | H19: 102139 | I19: 98174 | J19: 96632 | K19: 104614 | L19: 101921 | M19: 100499 | N19: 100601 | O19: 96360 | P19: 1282998
A20: 2 | B20: 8059 | C20: 9814 | D20: 10300 | E20: 10195 | F20: 9661 | G20: 7921 | H20: 8052 | I20: 8114 | J20: 8069 | K20: 7406 | L20: 7676 | M20: 7972 | N20: 8001 | O20: 8077 | P20: 119317
A21: 3 | B21: 622507 | C21: 608965 | D21: 605446 | E21: 607427 | F21: 615423 | G21: 629033 | H21: 658715 | I21: 676763 | J21: 670320 | K21: 679044 | L21: 698151 | M21: 713970 | N21: 717265 | O21: 716878 | P21: 9219907
A22: 4 | B22: 26130 | C22: 25628 | D22: 25479 | E22: 26631 | F22: 26000 | G22: 26079 | H22: 26482 | I22: 26776 | J22: 27827 | K22: 29701 | L22: 31655 | M22: 34158 | N22: 38736 | O22: 40598 | P22: 411880
A23: 5 | B23: 36408 | C23: 31320 | D23: 31534 | E23: 31236 | F23: 31711 | G23: 32641 | H23: 34227 | I23: 34763 | J23: 35195 | K23: 36124 | L23: 37100 | M23: 37819 | N23: 38551 | O23: 40424 | P23: 489053
A24: 6 | B24: 322635 | C24: 294076 | D24: 279811 | E24: 273856 | F24: 275585 | G24: 284292 | H24: 298377 | I24: 307593 | J24: 311875 | K24: 318810 | L24: 326567 | M24: 330972 | N24: 332772 | O24: 344432 | P24: 4301653
A25: 7 | B25: 1195274 | C25: 1181070 | D25: 1181400 | E25: 1197443 | F25: 1209566 | G25: 1242653 | H25: 1279288 | I25: 1290162 | J25: 1297603 | K25: 1307482 | L25: 1313457 | M25: 1307828 | N25: 1311748 | O25: 1294115 | P25: 17609089
A26: 8 | B26: 348250 | C26: 342971 | D26: 338881 | E26: 337807 | F26: 339917 | G26: 345135 | H26: 368186 | I26: 373049 | J26: 366463 | K26: 373139 | L26: 381496 | M26: 385515 | N26: 387084 | O26: 391220 | P26: 5079113
A27: 9 | B27: 302602 | C27: 306386 | D27: 317982 | E27: 331517 | F27: 349119 | G27: 361993 | H27: 376826 | I27: 387937 | J27: 369593 | K27: 376338 | L27: 403653 | M27: 423761 | N27: 429611 | O27: 426368 | P27: 5163686
A28: 10 | B28: 213052 | C28: 207814 | D28: 214571 | E28: 220314 | F28: 230405 | G28: 242756 | H28: 253945 | I28: 262747 | J28: 268368 | K28: 283269 | L28: 301105 | M28: 305457 | N28: 300206 | O28: 296170 | P28: 3600179
A29: 11 | B29: 228607 | C29: 221475 | D29: 212669 | E29: 218243 | F29: 212590 | G29: 201095 | H29: 198759 | I29: 193456 | J29: 202817 | K29: 205222 | L29: 211173 | M29: 214810 | N29: 211481 | O29: 211970 | P29: 2944367
A30: 12 | B30: 57714 | C30: 56139 | D30: 55370 | E30: 54849 | F30: 55387 | G30: 56183 | H30: 56773 | I30: 57800 | J30: 58504 | K30: 59221 | L30: 59536 | M30: 60879 | N30: 62863 | O30: 65604 | P30: 816822
... A38: 78 | B38: 463758 | C38: 478482 | D38: 509916 | E38: 561069 | F38: 606964 | G38: 649141 | H38: 808878 | I38: 754777 | J38: 618851 | K38: 738376 | L38: 752766 | M38: 694022 | N38: 668581 | O38: 616501 | P38: 8922082
A40: Total | B40: 6988782 | C40: 6881353 | D40: 6865753 | E40: 6921503 | F40: 7039106 | G40: 7214202 | H40: 7620677 | I40: 7712394 | J40: 7619544 | K40: 7882821 | L40: 8075059 | M40: 8144388 | N40: 8188733 | O40: 8197420 | P40: 105351735
A43: TBV FIGUUR
B44: 2011 | C44: 2012 | D44: 2013 | E44: 2014 | F44: 2015 | G44: 2016 | H44: 2017 | I44: 2018 | J44: 2019 | K44: 2020 | L44: 2021 | M44: 2022 | N44: 2023 | O44: 2024
A45: Baanblijvers | B45: =B7/1000 -> 5312.403 | C45: =C7/1000 -> 5332.636 | D45: =D7/1000 -> 5227.666 | E45: =E7/1000 -> 5148.045 | F45: =F7/1000 -> 5176.431 | G45: =G7/1000 -> 5242.988 | H45: =H7/1000 -> 5357.774 | I45: =I7/1000 -> 5552.592 | ... O45: =O7/1000 -> 6176.598
A46: Baanbeëindigers | baan-baan-wisselaars | B46: =B8/1000 -> 1122.938 | C46: =C8/1000 -> 1001.65 | D46: =D8/1000 -> 1037.592 | E46: =E8/1000 -> 1117.965 | F46: =F8/1000 -> 1175.544 | G46: =G8/1000 -> 1250.017 | H46: =H8/1000 -> 1305.975 | I46: =I8/1000 -> 1415.003 | ... O46: =O8/1000 -> 1316.475
A47: Baanbeëindigers | uitstroom niet-werknemersbaan | B47: =B10/1000 -> 657.018 | C47: =C10/1000 -> 684.786 | D47: =D10/1000 -> 643.707 | E47: =E10/1000 -> 627.534 | F47: =F10/1000 -> 601.986 | G47: =G10/1000 -> 581.53 | H47: =H10/1000 -> 592.127 | I47: =I10/1000 -> 702.842 | ... O47: =O10/1000 -> 768.718
A48: Totaal werknemers | B48: =B45+B46+B47 -> 7092.359 | C48: =C45+C46+C47 -> 7019.072 | D48: =D45+D46+D47 -> 6908.965 | E48: =E45+E46+E47 -> 6893.544 | F48: =F45+F46+F47 -> 6953.961 | G48: =G45+G46+G47 -> 7074.535 | H48: =H45+H46+H47 -> 7255.876 | I48: =I45+I46+I47 -> 7670.437 | ... O48: =O45+O46+O47 -> 8261.791
A49: Baanstarters | B49: =B9/1000 -> 553.441 | C49: =C9/1000 -> 547.067 | D49: =D9/1000 -> 600.495 | E49: =E9/1000 -> 655.493 | F49: =F9/1000 -> 687.131 | G49: =G9/1000 -> 721.197 | H49: =H9/1000 -> 956.928 | I49: =I9/1000 -> 744.799 | ... O49: =O9/1000 -> 704.347
A54: Figuur 2 | Q54: Gemiddelde
B55: 2011 | C55: 2012 | D55: 2013 | E55: 2014 | F55: 2015 | G55: 2016 | H55: 2017 | I55: 2018 | J55: 2019 | K55: 2020 | L55: 2021 | M55: 2022 | N55: 2023 | O55: 2024 | Q55: 2011-2025
A56: Baanblijvers | B56: =B45/B$48 -> 0.74903188 | C56: =C45/C$48 -> 0.75973519 | D56: =D45/D$48 -> 0.75664966 | E56: =E45/E$48 -> 0.74679222 | F56: =F45/F$48 -> 0.74438597 | G56: =G45/G$48 -> 0.74110708 | H56: =H45/H$48 -> 0.73840485 | I56: =I45/I$48 -> 0.72389513 | ... O56: =O45/O$48 -> 0.74761005 | Q56: =AVERAGE(B56:O56) -> 0.74259367
A57: Baan-baanwisselaars | B57: =B46/B$48 -> 0.15833068 | C57: =C46/C$48 -> 0.14270405 | D57: =D46/D$48 -> 0.15018053 | E57: =E46/E$48 -> 0.16217565 | F57: =F46/F$48 -> 0.16904668 | G57: =G46/G$48 -> 0.17669246 | H57: =H46/H$48 -> 0.17998861 | I57: =I46/I$48 -> 0.18447489 | ... O57: =O46/O$48 -> 0.15934499 | Q57: =AVERAGE(B57:O57) -> 0.16679906
A58: Uitstroom naar niet-werknemersbaan | B58: =B47/B$48 -> 0.092637443 | C58: =C47/C$48 -> 0.09756076 | D58: =D47/D$48 -> 0.093169816 | E58: =E47/E$48 -> 0.091032131 | F58: =F47/F$48 -> 0.086567353 | G58: =G47/G$48 -> 0.082200456 | H58: =H47/H$48 -> 0.081606549 | I58: =I47/I$48 -> 0.091629981 | ... O58: =O47/O$48 -> 0.093044958 | Q58: =AVERAGE(B58:O58) -> 0.090607264
A59: Instroom vanuit niet-werknemersbaan | B59: =B49/(B40/1000) -> 0.079189907 | C59: =C49/(C40/1000) -> 0.079499918 | D59: =D49/(D40/1000) -> 0.087462366 | E59: =E49/(E40/1000) -> 0.094703853 | F59: =F49/(F40/1000) -> 0.097616231 | G59: =G49/(G40/1000) -> 0.099969061 | H59: =H49/(H40/1000) -> 0.12556995 | I59: =I49/(I40/1000) -> 0.0965717 | ... O59: =O49/(O40/1000) -> 0.08592301 | Q59: =AVERAGE(B59:O59) -> 0.094683336
A60: Totaal werknemers | B60: =B48/B$48 -> 1 | C60: =C48/C$48 -> 1 | D60: =D48/D$48 -> 1 | E60: =E48/E$48 -> 1 | F60: =F48/F$48 -> 1 | G60: =G48/G$48 -> 1 | H60: =H48/H$48 -> 1 | I60: =I48/I$48 -> 1 | ... O60: =O48/O$48 -> 1 | Q60: =AVERAGE(B60:O60) -> 1

Sheet Figuur_4a
A1: switch_beid_stream==0 | B1: year
A2: Geslacht | B2: 2011 | C2: 2012 | D2: 2013 | E2: 2014 | F2: 2015 | G2: 2016 | H2: 2017 | I2: 2018 | J2: 2019 | K2: 2020 | L2: 2021 | M2: 2022 | N2: 2023 | O2: 2024 | P2: Total | U2: TOTAAL WERKNEMERS
V3: 2011 | W3: 2012 | X3: 2013 | Y3: 2014 | Z3: 2015 | AA3: 2016 | AB3: 2017 | AC3: 2018 | AD3: 2019 | AE3: 2020 | AF3: 2021 | AG3: 2022 | AH3: 2023 | AI3: 2024 | AJ3: Total
A4: Man | B4: 3703155 | C4: 3644380 | D4: 3577890 | E4: 3567381 | F4: 3605517 | G4: 3666120 | H4: 3753429 | I4: 3990436 | J4: 4014146 | K4: 3931681 | L4: 4065811 | M4: 4156910 | N4: 4181943 | O4: 4197746 | P4: 54056545 | U4: man | V4: =B4/1000 -> 3703.155 | W4: =C4/1000 -> 3644.38 | X4: =D4/1000 -> 3577.89 | Y4: =E4/1000 -> 3567.381 | Z4: =F4/1000 -> 3605.517 | AA4: =G4/1000 -> 3666.12 | AB4: =H4/1000 -> 3753.429 | AC4: =I4/1000 -> 3990.436 | ... AI4: =O4/1000 -> 4197.746 | AJ4: =(O4+O12+O28)/1000 -> 4869.42
A5: Vrouw | B5: 3389204 | C5: 3374692 | D5: 3331075 | E5: 3326163 | F5: 3348444 | G5: 3408415 | H5: 3502447 | I5: 3680001 | J5: 3751781 | K5: 3734384 | L5: 3872474 | M5: 3986927 | N5: 4037272 | O5: 4064045 | P5: 50807324 | U5: vrouw | V5: =B5/1000 -> 3389.204 | W5: =C5/1000 -> 3374.692 | X5: =D5/1000 -> 3331.075 | Y5: =E5/1000 -> 3326.163 | Z5: =F5/1000 -> 3348.444 | AA5: =G5/1000 -> 3408.415 | AB5: =H5/1000 -> 3502.447 | AC5: =I5/1000 -> 3680.001 | ... AI5: =O5/1000 -> 4064.045 | AJ5: =(O5+O13+O29)/1000 -> 4708.846
A7: Total | B7: 7092359 | C7: 7019072 | D7: 6908965 | E7: 6893544 | F7: 6953961 | G7: 7074535 | H7: 7255876 | I7: 7670437 | J7: 7765927 | K7: 7666065 | L7: 7938285 | M7: 8143837 | N7: 8219215 | O7: 8261791 | P7: 104863869 | U7: Total | V7: =B7/1000 -> 7092.359 | W7: =C7/1000 -> 7019.072 | X7: =D7/1000 -> 6908.965 | Y7: =E7/1000 -> 6893.544 | Z7: =F7/1000 -> 6953.961 | AA7: =G7/1000 -> 7074.535 | AB7: =H7/1000 -> 7255.876 | AC7: =I7/1000 -> 7670.437 | ... AI7: =O7/1000 -> 8261.791 | AJ7: =(O7+O15+O31)/1000 -> 9578.266
A9: switch_beid_stream==1 | B9: year
A10: Geslacht | B10: 2011 | C10: 2012 | D10: 2013 | E10: 2014 | F10: 2015 | G10: 2016 | H10: 2017 | I10: 2018 | J10: 2019 | K10: 2020 | L10: 2021 | M10: 2022 | N10: 2023 | O10: 2024 | P10: Total | U10: Figuur
V11: 2011 | W11: 2012 | X11: 2013 | Y11: 2014 | Z11: 2015 | AA11: 2016 | AB11: 2017 | AC11: 2018 | AD11: 2019 | AE11: 2020 | AF11: 2021 | AG11: 2022 | AH11: 2023 | AI11: 2024 | AJ11: Total
A12: Man | B12: 583750 | C12: 524751 | D12: 555207 | E12: 565006 | F12: 598386 | G12: 641873 | H12: 670052 | I12: 720666 | J12: 623068 | K12: 634913 | L12: 721995 | M12: 710432 | N12: 674278 | O12: 671674 | P12: 8896051 | U12: man | V12: =B12/(V4*1000) -> 0.15763585 | W12: =C12/(W4*1000) -> 0.1439891 | X12: =D12/(X4*1000) -> 0.15517721 | Y12: =E12/(Y4*1000) -> 0.15838118 | Z12: =F12/(Z4*1000) -> 0.16596399 | AA12: =G12/(AA4*1000) -> 0.17508238 | AB12: =H12/(AB4*1000) -> 0.1785173 | AC12: =I12/(AC4*1000) -> 0.18059831 | ... AI12: =O12/(AI4*1000) -> 0.16000825 | AJ12: =O12/(AJ4*1000) -> 0.13793717
A13: Vrouw | B13: 539188 | C13: 476899 | D13: 482385 | E13: 552959 | F13: 577158 | G13: 608144 | H13: 635923 | I13: 694337 | J13: 618270 | K13: 628596 | L13: 730937 | M13: 722135 | N13: 711886 | O13: 644801 | P13: 8623618 | U13: vrouw | V13: =B13/(V5*1000) -> 0.15908986 | W13: =C13/(W5*1000) -> 0.1413163 | X13: =D13/(X5*1000) -> 0.14481361 | Y13: =E13/(Y5*1000) -> 0.16624531 | Z13: =F13/(Z5*1000) -> 0.17236603 | AA13: =G13/(AA5*1000) -> 0.17842428 | AB13: =H13/(AB5*1000) -> 0.18156535 | AC13: =I13/(AC5*1000) -> 0.18867848 | ... AI13: =O13/(AI5*1000) -> 0.15865991 | AJ13: =O13/(AJ5*1000) -> 0.13693397
A15: Total | B15: 1122938 | C15: 1001650 | D15: 1037592 | E15: 1117965 | F15: 1175544 | G15: 1250017 | H15: 1305975 | I15: 1415003 | J15: 1241338 | K15: 1263509 | L15: 1452932 | M15: 1432567 | N15: 1386164 | O15: 1316475 | P15: 17519669 | U15: Total | V15: =B15/(V7*1000) -> 0.15833068 | W15: =C15/(W7*1000) -> 0.14270405 | X15: =D15/(X7*1000) -> 0.15018053 | Y15: =E15/(Y7*1000) -> 0.16217565 | Z15: =F15/(Z7*1000) -> 0.16904668 | AA15: =G15/(AA7*1000) -> 0.17669246 | AB15: =H15/(AB7*1000) -> 0.17998861 | AC15: =I15/(AC7*1000) -> 0.18447489 | ... AI15: =O15/(AI7*1000) -> 0.15934499 | AJ15: =O15/(AJ7*1000) -> 0.13744398

Sheet Figuur_4b
A1: switch_beid_stream==0 | B1: year
A2: Age in 10y categories | B2: 2011 | C2: 2012 | D2: 2013 | E2: 2014 | F2: 2015 | G2: 2016 | H2: 2017 | I2: 2018 | J2: 2019 | K2: 2020 | L2: 2021 | M2: 2022 | N2: 2023 | O2: 2024 | P2: Total | U2: TOTAAL WERKNEMERS
V3: 2011 | W3: 2012 | X3: 2013 | Y3: 2014 | Z3: 2015 | AA3: 2016 | AB3: 2017 | AC3: 2018 | AD3: 2019 | AE3: 2020 | AF3: 2021 | AG3: 2022 | AH3: 2023 | AI3: 2024 | AJ3: Total
A4: 15 tot 25 | B4: 1189871 | C4: 1154817 | D4: 1115700 | E4: 1111226 | F4: 1135276 | G4: 1172995 | H4: 1229849 | I4: 1337699 | J4: 1342703 | K4: 1296484 | L4: 1401408 | M4: 1455626 | N4: 1465212 | O4: 1454662 | P4: 17863528 | U4: 15 tot 25 | V4: =B4/1000 -> 1189.871 | W4: =C4/1000 -> 1154.817 | X4: =D4/1000 -> 1115.7 | Y4: =E4/1000 -> 1111.226 | Z4: =F4/1000 -> 1135.276 | AA4: =G4/1000 -> 1172.995 | AB4: =H4/1000 -> 1229.849 | AC4: =I4/1000 -> 1337.699 | ... AJ4: =P4/1000 -> 17863.528
A5: 25 tot 35 | B5: 1521501 | C5: 1507962 | D5: 1486778 | E5: 1488491 | F5: 1506927 | G5: 1540951 | H5: 1590201 | I5: 1709314 | J5: 1736018 | K5: 1716845 | L5: 1781620 | M5: 1824746 | N5: 1845113 | O5: 1863059 | P5: 23119526 | U5: 25 tot 35 | V5: =B5/1000 -> 1521.501 | W5: =C5/1000 -> 1507.962 | X5: =D5/1000 -> 1486.778 | Y5: =E5/1000 -> 1488.491 | Z5: =F5/1000 -> 1506.927 | AA5: =G5/1000 -> 1540.951 | AB5: =H5/1000 -> 1590.201 | AC5: =I5/1000 -> 1709.314 | ... AJ5: =P5/1000 -> 23119.526
A6: 35 tot 45 | B6: 1649962 | C6: 1594173 | D6: 1532228 | E6: 1481957 | F6: 1451955 | G6: 1435727 | H6: 1432364 | I6: 1486998 | J6: 1492411 | K6: 1483025 | L6: 1533242 | M6: 1577768 | N6: 1598335 | O6: 1620052 | P6: 21370197 | U6: 35 tot 45 | V6: =B6/1000 -> 1649.962 | W6: =C6/1000 -> 1594.173 | X6: =D6/1000 -> 1532.228 | Y6: =E6/1000 -> 1481.957 | Z6: =F6/1000 -> 1451.955 | AA6: =G6/1000 -> 1435.727 | AB6: =H6/1000 -> 1432.364 | AC6: =I6/1000 -> 1486.998 | ... AJ6: =P6/1000 -> 21370.197
A7: 45 tot 55 | B7: 1661066 | C7: 1653705 | D7: 1631878 | E7: 1629258 | F7: 1636271 | G7: 1643795 | H7: 1653539 | I7: 1687713 | J7: 1667297 | K7: 1618588 | L7: 1619316 | M7: 1611651 | N7: 1583331 | O7: 1547682 | P7: 22845090 | U7: 45 tot 55 | V7: =B7/1000 -> 1661.066 | W7: =C7/1000 -> 1653.705 | X7: =D7/1000 -> 1631.878 | Y7: =E7/1000 -> 1629.258 | Z7: =F7/1000 -> 1636.271 | AA7: =G7/1000 -> 1643.795 | AB7: =H7/1000 -> 1653.539 | AC7: =I7/1000 -> 1687.713 | ... AJ7: =P7/1000 -> 22845.09
A8: 55 tot 65 | B8: 994028 | C8: 1026313 | D8: 1055393 | E8: 1092896 | F8: 1122581 | G8: 1167053 | H8: 1217795 | I8: 1292887 | J8: 1344853 | K8: 1365638 | L8: 1405258 | M8: 1447868 | N8: 1475729 | O8: 1501990 | P8: 17510282 | U8: 55 tot 65 | V8: =B8/1000 -> 994.028 | W8: =C8/1000 -> 1026.313 | X8: =D8/1000 -> 1055.393 | Y8: =E8/1000 -> 1092.896 | Z8: =F8/1000 -> 1122.581 | AA8: =G8/1000 -> 1167.053 | AB8: =H8/1000 -> 1217.795 | AC8: =I8/1000 -> 1292.887 | ... AJ8: =P8/1000 -> 17510.282
A9: 65 tot 75 | B9: 75931 | C9: 82102 | D9: 86988 | E9: 89716 | F9: 100951 | G9: 114014 | H9: 132128 | I9: 155826 | J9: 182645 | K9: 185485 | L9: 197441 | M9: 226178 | N9: 251495 | O9: 274346 | P9: 2155246 | U9: 65 tot 75 | V9: =B9/1000 -> 75.931 | W9: =C9/1000 -> 82.102 | X9: =D9/1000 -> 86.988 | Y9: =E9/1000 -> 89.716 | Z9: =F9/1000 -> 100.951 | AA9: =G9/1000 -> 114.014 | AB9: =H9/1000 -> 132.128 | AC9: =I9/1000 -> 155.826 | ... AJ9: =P9/1000 -> 2155.246
A11: Total | B11: 7092359 | C11: 7019072 | D11: 6908965 | E11: 6893544 | F11: 6953961 | G11: 7074535 | H11: 7255876 | I11: 7670437 | J11: 7765927 | K11: 7666065 | L11: 7938285 | M11: 8143837 | N11: 8219215 | O11: 8261791 | P11: 104863869 | U11: Total | V11: =B11/1000 -> 7092.359 | W11: =C11/1000 -> 7019.072 | X11: =D11/1000 -> 6908.965 | Y11: =E11/1000 -> 6893.544 | Z11: =F11/1000 -> 6953.961 | AA11: =G11/1000 -> 7074.535 | AB11: =H11/1000 -> 7255.876 | AC11: =I11/1000 -> 7670.437 | ... AJ11: =P11/1000 -> 104863.87
V12: =#REF! -> #REF! | W12: =#REF! -> #REF! | X12: =#REF! -> #REF! | Y12: =#REF! -> #REF! | Z12: =#REF! -> #REF! | AA12: =#REF! -> #REF! | AB12: =#REF! -> #REF! | AC12: =#REF! -> #REF! | ... AH12: =#REF! -> #REF!
A13: switch_beid_stream==1 | B13: year
A14: Age in 10y categories | B14: 2011 | C14: 2012 | D14: 2013 | E14: 2014 | F14: 2015 | G14: 2016 | H14: 2017 | I14: 2018 | J14: 2019 | K14: 2020 | L14: 2021 | M14: 2022 | N14: 2023 | O14: 2024 | P14: Total | U14: Figuur
V15: 2011 | W15: 2012 | X15: 2013 | Y15: 2014 | Z15: 2015 | AA15: 2016 | AB15: 2017 | AC15: 2018 | AD15: 2019 | AE15: 2020 | AF15: 2021 | AG15: 2022 | AH15: 2023 | AI15: 2024 | AJ15: Total
A16: 15 tot 25 | B16: 351885 | C16: 323078 | D16: 324032 | E16: 356477 | F16: 384605 | G16: 399736 | H16: 421216 | I16: 440998 | J16: 410336 | K16: 420402 | L16: 483052 | M16: 478100 | N16: 461155 | O16: 453307 | P16: 5708379 | U16: 15 tot 25 | V16: =B16/(V4*1000) -> 0.29573374 | W16: =C16/(W4*1000) -> 0.27976554 | X16: =D16/(X4*1000) -> 0.29042933 | Y16: =E16/(Y4*1000) -> 0.32079613 | Z16: =F16/(Z4*1000) -> 0.33877665 | AA16: =G16/(AA4*1000) -> 0.34078236 | AB16: =H16/(AB4*1000) -> 0.34249408 | AC16: =I16/(AC4*1000) -> 0.32966908 | ... AJ16: =P16/(AJ4*1000) -> 0.31955496
A17: 25 tot 35 | B17: 283049 | C17: 252179 | D17: 268993 | E17: 296273 | F17: 322597 | G17: 340113 | H17: 362740 | I17: 389743 | J17: 340860 | K17: 349533 | L17: 398689 | M17: 377758 | N17: 362328 | O17: 352802 | P17: 4697657 | U17: 25 tot 35 | V17: =B17/(V5*1000) -> 0.18603274 | W17: =C17/(W5*1000) -> 0.16723167 | X17: =D17/(X5*1000) -> 0.18092345 | Y17: =E17/(Y5*1000) -> 0.19904252 | Z17: =F17/(Z5*1000) -> 0.21407606 | AA17: =G17/(AA5*1000) -> 0.2207163 | AB17: =H17/(AB5*1000) -> 0.22810953 | AC17: =I17/(AC5*1000) -> 0.22801135 | ... AJ17: =P17/(AJ5*1000) -> 0.20319002
A18: 35 tot 45 | B18: 220912 | C18: 186057 | D18: 186761 | E18: 195381 | F18: 199112 | G18: 212014 | H18: 218844 | I18: 239190 | J18: 201630 | K18: 203680 | L18: 239906 | M18: 238697 | N18: 227408 | O18: 213139 | P18: 2982731 | U18: 35 tot 45 | V18: =B18/(V6*1000) -> 0.13388914 | W18: =C18/(W6*1000) -> 0.11671067 | X18: =D18/(X6*1000) -> 0.12188852 | Y18: =E18/(Y6*1000) -> 0.13183986 | Z18: =F18/(Z6*1000) -> 0.13713373 | AA18: =G18/(AA6*1000) -> 0.14767014 | AB18: =H18/(AB6*1000) -> 0.15278519 | AC18: =I18/(AC6*1000) -> 0.16085428 | ... AJ18: =P18/(AJ6*1000) -> 0.13957433
A19: 45 tot 55 | B19: 182850 | C19: 159966 | D19: 167448 | E19: 177113 | F19: 178399 | G19: 195491 | H19: 199251 | I19: 221834 | J19: 182655 | K19: 179257 | L19: 204022 | M19: 201866 | N19: 189980 | O19: 168407 | P19: 2608539 | U19: 45 tot 55 | V19: =B19/(V7*1000) -> 0.11007991 | W19: =C19/(W7*1000) -> 0.096731884 | X19: =D19/(X7*1000) -> 0.10261061 | Y19: =E19/(Y7*1000) -> 0.10870777 | Z19: =F19/(Z7*1000) -> 0.10902778 | AA19: =G19/(AA7*1000) -> 0.11892663 | AB19: =H19/(AB7*1000) -> 0.12049973 | AC19: =I19/(AC7*1000) -> 0.13144059 | ... AJ19: =P19/(AJ7*1000) -> 0.11418379
A20: 55 tot 65 | B20: 78384 | C20: 73790 | D20: 83362 | E20: 86305 | F20: 83569 | G20: 94924 | H20: 94446 | I20: 112690 | J20: 95396 | K20: 100400 | L20: 115255 | M20: 122634 | N20: 129262 | O20: 112412 | P20: 1382829 | U20: 55 tot 65 | V20: =B20/(V8*1000) -> 0.078854922 | W20: =C20/(W8*1000) -> 0.071898144 | X20: =D20/(X8*1000) -> 0.07898669 | Y20: =E20/(Y8*1000) -> 0.078969088 | Z20: =F20/(Z8*1000) -> 0.074443626 | AA20: =G20/(AA8*1000) -> 0.081336495 | AB20: =H20/(AB8*1000) -> 0.077554925 | AC20: =I20/(AC8*1000) -> 0.087161523 | ... AJ20: =P20/(AJ8*1000) -> 0.0789724
A21: 65 tot 75 | B21: 5858 | C21: 6580 | D21: 6996 | E21: 6416 | F21: 7262 | G21: 7739 | H21: 9478 | I21: 10548 | J21: 10461 | K21: 10237 | L21: 12008 | M21: 13512 | N21: 16031 | O21: 16408 | P21: 139534 | U21: 65 tot 75 | V21: =B21/(V9*1000) -> 0.077148991 | W21: =C21/(W9*1000) -> 0.080144211 | X21: =D21/(X9*1000) -> 0.080424886 | Y21: =E21/(Y9*1000) -> 0.071514557 | Z21: =F21/(Z9*1000) -> 0.07193589 | AA21: =G21/(AA9*1000) -> 0.067877629 | AB21: =H21/(AB9*1000) -> 0.071733471 | AC21: =I21/(AC9*1000) -> 0.067690886 | ... AJ21: =P21/(AJ9*1000) -> 0.064741565
A23: Total | B23: 1122938 | C23: 1001650 | D23: 1037592 | E23: 1117965 | F23: 1175544 | G23: 1250017 | H23: 1305975 | I23: 1415003 | J23: 1241338 | K23: 1263509 | L23: 1452932 | M23: 1432567 | N23: 1386164 | O23: 1316475 | P23: 17519669 | U23: Total | V23: =B23/(V11*1000) -> 0.15833068 | W23: =C23/(W11*1000) -> 0.14270405 | X23: =D23/(X11*1000) -> 0.15018053 | Y23: =E23/(Y11*1000) -> 0.16217565 | Z23: =F23/(Z11*1000) -> 0.16904668 | AA23: =G23/(AA11*1000) -> 0.17669246 | AB23: =H23/(AB11*1000) -> 0.17998861 | AC23: =I23/(AC11*1000) -> 0.18447489 | ... AJ23: =P23/(AJ11*1000) -> 0.1670706
V24: =#REF! -> #REF! | W24: =#REF! -> #REF! | X24: =#REF! -> #REF! | Y24: =#REF! -> #REF! | Z24: =#REF! -> #REF! | AA24: =#REF! -> #REF! | AB24: =#REF! -> #REF! | AC24: =#REF! -> #REF! | ... AI24: =#REF! -> #REF!

Sheet Figuur_4c
A1: switch_beid_stream==0 | B1: year
A2: Highest level of education achieved, SOI2016 | B2: 2011 | C2: 2012 | D2: 2013 | E2: 2014 | F2: 2015 | G2: 2016 | H2: 2017 | I2: 2018 | J2: 2019 | K2: 2020 | L2: 2021 | M2: 2022 | N2: 2023 | O2: 2024 | P2: Total | V2: TOTAAL WERKNEMERS
W3: 2011 | X3: 2012 | Y3: 2013 | Z3: 2014 | AA3: 2015 | AB3: 2016 | AC3: 2017 | AD3: 2018 | AE3: 2019 | AF3: 2020 | AG3: 2021 | AH3: 2022 | AI3: 2023 | AJ3: 2024
A4: Lower | B4: 955599 | C4: 941458 | D4: 923864 | E4: 919005 | F4: 929647 | G4: 977816 | H4: 1019370 | I4: 1068282 | J4: 1096919 | K4: 1031919 | L4: 1049004 | M4: 1097128 | N4: 1114154 | O4: 1102287 | P4: 14226452 | V4: mbo1 of lager | W4: =B4/1000 -> 955.599 | X4: =C4/1000 -> 941.458 | Y4: =D4/1000 -> 923.864 | Z4: =E4/1000 -> 919.005 | AA4: =F4/1000 -> 929.647 | AB4: =G4/1000 -> 977.816 | AC4: =H4/1000 -> 1019.37 | AD4: =I4/1000 -> 1068.282 | ... AJ4: =O4/1000 -> 1102.287
A5: Medium | B5: 1792442 | C5: 1881062 | D5: 1982171 | E5: 2007412 | F5: 2065699 | G5: 2172154 | H5: 2286551 | I5: 2368697 | J5: 2434668 | K5: 2464033 | L5: 2578062 | M5: 2604257 | N5: 2618333 | O5: 2637730 | P5: 31893271 | V5: mbo2-4 | W5: =B5/1000 -> 1792.442 | X5: =C5/1000 -> 1881.062 | Y5: =D5/1000 -> 1982.171 | Z5: =E5/1000 -> 2007.412 | AA5: =F5/1000 -> 2065.699 | AB5: =G5/1000 -> 2172.154 | AC5: =H5/1000 -> 2286.551 | AD5: =I5/1000 -> 2368.697 | ... AJ5: =O5/1000 -> 2637.73
A6: Bachelor | B6: 873292 | C6: 908801 | D6: 1063967 | E6: 1083482 | F6: 1121771 | G6: 1170844 | H6: 1240399 | I6: 1317929 | J6: 1369607 | K6: 1405119 | L6: 1454222 | M6: 1501112 | N6: 1479340 | O6: 1514023 | P6: 17503908 | V6: bachelor | W6: =B6/1000 -> 873.292 | X6: =C6/1000 -> 908.801 | Y6: =D6/1000 -> 1063.967 | Z6: =E6/1000 -> 1083.482 | AA6: =F6/1000 -> 1121.771 | AB6: =G6/1000 -> 1170.844 | AC6: =H6/1000 -> 1240.399 | AD6: =I6/1000 -> 1317.929 | ... AJ6: =O6/1000 -> 1514.023
A7: Master | B7: 450382 | C7: 474445 | D7: 602890 | E7: 633155 | F7: 660238 | G7: 689592 | H7: 723145 | I7: 754142 | J7: 794064 | K7: 829354 | L7: 877356 | M7: 920881 | N7: 1007265 | O7: 1027186 | P7: 10444095 | V7: master of hoger | W7: =B7/1000 -> 450.382 | X7: =C7/1000 -> 474.445 | Y7: =D7/1000 -> 602.89 | Z7: =E7/1000 -> 633.155 | AA7: =F7/1000 -> 660.238 | AB7: =G7/1000 -> 689.592 | AC7: =H7/1000 -> 723.145 | AD7: =I7/1000 -> 754.142 | ... AJ7: =O7/1000 -> 1027.186
B8: 3020644 | C8: 2813306 | D8: 2336073 | E8: 2250490 | F8: 2176606 | G8: 2064129 | H8: 1986411 | I8: 2161387 | J8: 2070669 | K8: 1935640 | L8: 1979641 | M8: 2020459 | N8: 2000123 | O8: 1980565 | P8: 30796143 | V8: onbekend | W8: =B8/1000 -> 3020.644 | X8: =C8/1000 -> 2813.306 | Y8: =D8/1000 -> 2336.073 | Z8: =E8/1000 -> 2250.49 | AA8: =F8/1000 -> 2176.606 | AB8: =G8/1000 -> 2064.129 | AC8: =H8/1000 -> 1986.411 | AD8: =I8/1000 -> 2161.387 | ... AJ8: =O8/1000 -> 1980.565
A10: Total | B10: 7092359 | C10: 7019072 | D10: 6908965 | E10: 6893544 | F10: 6953961 | G10: 7074535 | H10: 7255876 | I10: 7670437 | J10: 7765927 | K10: 7666065 | L10: 7938285 | M10: 8143837 | N10: 8219215 | O10: 8261791 | P10: 104863869 | V10: totaal | W10: =B10/1000 -> 7092.359 | X10: =C10/1000 -> 7019.072 | Y10: =D10/1000 -> 6908.965 | Z10: =E10/1000 -> 6893.544 | AA10: =F10/1000 -> 6953.961 | AB10: =G10/1000 -> 7074.535 | AC10: =H10/1000 -> 7255.876 | AD10: =I10/1000 -> 7670.437 | ... AJ10: =O10/1000 -> 8261.791
V11: totaal | W11: =#REF! -> #REF! | X11: =#REF! -> #REF! | Y11: =#REF! -> #REF! | Z11: =#REF! -> #REF! | AA11: =#REF! -> #REF! | AB11: =#REF! -> #REF! | AC11: =#REF! -> #REF! | AD11: =#REF! -> #REF! | ... AJ11: =#REF! -> #REF!
A12: switch_beid_stream==1 | B12: year
A13: Highest level of education achieved, SOI2016 | B13: 2011 | C13: 2012 | D13: 2013 | E13: 2014 | F13: 2015 | G13: 2016 | H13: 2017 | I13: 2018 | J13: 2019 | K13: 2020 | L13: 2021 | M13: 2022 | N13: 2023 | O13: 2024 | P13: Total | V13: Figuur
W14: 2011 | X14: 2012 | Y14: 2013 | Z14: 2014 | AA14: 2015 | AB14: 2016 | AC14: 2017 | AD14: 2018 | AE14: 2019 | AF14: 2020 | AG14: 2021 | AH14: 2022 | AI14: 2023 | AJ14: 2024
A15: Lower | B15: 221550 | C15: 200760 | D15: 191827 | E15: 212568 | F15: 232287 | G15: 249604 | H15: 268829 | I15: 281122 | J15: 256787 | K15: 247979 | L15: 285696 | M15: 286855 | N15: 281227 | O15: 266132 | P15: 3483223 | V15: mbo1 of lager | W15: =B15/(W4*1000) -> 0.23184411 | X15: =C15/(X4*1000) -> 0.21324371 | Y15: =D15/(Y4*1000) -> 0.20763554 | Z15: =E15/(Z4*1000) -> 0.23130233 | AA15: =F15/(AA4*1000) -> 0.24986581 | AB15: =G15/(AB4*1000) -> 0.25526684 | AC15: =H15/(AC4*1000) -> 0.26372073 | AD15: =I15/(AD4*1000) -> 0.26315336 | ... AJ15: =O15/(AJ4*1000) -> 0.24143621
A16: Medium | B16: 368267 | C16: 348115 | D16: 395935 | E16: 431947 | F16: 468744 | G16: 487958 | H16: 516537 | I16: 519668 | J16: 461881 | K16: 477427 | L16: 549345 | M16: 522529 | N16: 498846 | O16: 469014 | P16: 6516213 | V16: mbo2-4 | W16: =B16/(W5*1000) -> 0.20545546 | X16: =C16/(X5*1000) -> 0.18506301 | Y16: =D16/(Y5*1000) -> 0.19974815 | Z16: =E16/(Z5*1000) -> 0.21517606 | AA16: =F16/(AA5*1000) -> 0.22691786 | AB16: =G16/(AB5*1000) -> 0.22464245 | AC16: =H16/(AC5*1000) -> 0.22590224 | AD16: =I16/(AD5*1000) -> 0.21938982 | ... AJ16: =O16/(AJ5*1000) -> 0.17780971
A17: Bachelor | B17: 142608 | C17: 130055 | D17: 163596 | E17: 185118 | F17: 200792 | G17: 211443 | H17: 222683 | I17: 243142 | J17: 209595 | K17: 222348 | L17: 249825 | M17: 244007 | N17: 226787 | O17: 214745 | P17: 2866744 | V17: bachelor | W17: =B17/(W6*1000) -> 0.16329933 | X17: =C17/(X6*1000) -> 0.14310614 | Y17: =D17/(Y6*1000) -> 0.15376041 | Z17: =E17/(Z6*1000) -> 0.17085471 | AA17: =F17/(AA6*1000) -> 0.17899553 | AB17: =G17/(AB6*1000) -> 0.18059024 | AC17: =H17/(AC6*1000) -> 0.1795253 | AD17: =I17/(AD6*1000) -> 0.18448794 | ... AJ17: =O17/(AJ6*1000) -> 0.14183734
A18: Master | B18: 73979 | C18: 66487 | D18: 86789 | E18: 100765 | F18: 106936 | G18: 119753 | H18: 118437 | I18: 131533 | J18: 115487 | K18: 124485 | L18: 136870 | M18: 135937 | N18: 138680 | O18: 133583 | P18: 1589721 | V18: master of hoger | W18: =B18/(W7*1000) -> 0.16425834 | X18: =C18/(X7*1000) -> 0.14013637 | Y18: =D18/(Y7*1000) -> 0.14395495 | Z18: =E18/(Z7*1000) -> 0.15914744 | AA18: =F18/(AA7*1000) -> 0.16196584 | AB18: =G18/(AB7*1000) -> 0.17365776 | AC18: =H18/(AC7*1000) -> 0.16378043 | AD18: =I18/(AD7*1000) -> 0.1744141 | ... AJ18: =O18/(AJ7*1000) -> 0.13004753
B19: 316534 | C19: 256233 | D19: 199445 | E19: 187567 | F19: 166785 | G19: 181259 | H19: 179489 | I19: 239538 | J19: 197588 | K19: 191270 | L19: 231196 | M19: 243239 | N19: 240624 | O19: 233001 | P19: 3063768 | V19: onbekend | W19: =B19/(W8*1000) -> 0.10479024 | X19: =C19/(X8*1000) -> 0.091078965 | Y19: =D19/(Y8*1000) -> 0.085376185 | Z19: =E19/(Z8*1000) -> 0.08334496 | AA19: =F19/(AA8*1000) -> 0.076626179 | AB19: =G19/(AB8*1000) -> 0.087813795 | AC19: =H19/(AC8*1000) -> 0.09035844 | AD19: =I19/(AD8*1000) -> 0.11082606 | ... AJ19: =O19/(AJ8*1000) -> 0.1176437
A20: Total
B21: 1122938 | C21: 1001650 | D21: 1037592 | E21: 1117965 | F21: 1175544 | G21: 1250017 | H21: 1305975 | I21: 1415003 | J21: 1241338 | K21: 1263509 | L21: 1452932 | M21: 1432567 | N21: 1386164 | O21: 1316475 | P21: 17519669 | V21: totaal | W21: =B21/(W10*1000) -> 0.15833068 | X21: =C21/(X10*1000) -> 0.14270405 | Y21: =D21/(Y10*1000) -> 0.15018053 | Z21: =E21/(Z10*1000) -> 0.16217565 | AA21: =F21/(AA10*1000) -> 0.16904668 | AB21: =G21/(AB10*1000) -> 0.17669246 | AC21: =H21/(AC10*1000) -> 0.17998861 | AD21: =I21/(AD10*1000) -> 0.18447489 | ... AJ21: =O21/(AJ10*1000) -> 0.15934499
V22: totaal | W22: =#REF! -> #REF! | X22: =#REF! -> #REF! | Y22: =#REF! -> #REF! | Z22: =#REF! -> #REF! | AA22: =#REF! -> #REF! | AB22: =#REF! -> #REF! | AC22: =#REF! -> #REF! | AD22: =#REF! -> #REF! | ... AJ22: =#REF! -> #REF!

Sheet Figuur_4d
A1: switch_beid_stream==0 | B1: year
A2: Contract type | B2: 2011 | C2: 2012 | D2: 2013 | E2: 2014 | F2: 2015 | G2: 2016 | H2: 2017 | I2: 2018 | J2: 2019 | K2: 2020 | L2: 2021 | M2: 2022 | N2: 2023 | O2: 2024 | P2: Total | U2: TOTAAL WERKNEMERS
V3: 2011 | W3: 2012 | X3: 2013 | Y3: 2014 | Z3: 2015 | AA3: 2016 | AB3: 2017 | AC3: 2018 | AD3: 2019 | AE3: 2020 | AF3: 2021 | AG3: 2022 | AH3: 2023 | AI3: 2024
A4: Onbepaalde tijd | B4: 4879788 | C4: 4791139 | D4: 4676980 | E4: 4579158 | F4: 4492097 | G4: 4504087 | H4: 4535536 | I4: 4674091 | J4: 4781800 | K4: 5121134 | L4: 5118247 | M4: 5184282 | N4: 5291011 | O4: 5386420 | P4: 68015770 | U4: vast | V4: =B4/1000 -> 4879.788 | W4: =C4/1000 -> 4791.139 | X4: =D4/1000 -> 4676.98 | Y4: =E4/1000 -> 4579.158 | Z4: =F4/1000 -> 4492.097 | AA4: =G4/1000 -> 4504.087 | AB4: =H4/1000 -> 4535.536 | AC4: =I4/1000 -> 4674.091 | ... AI4: =O4/1000 -> 5386.42
A5: Bepaalde tijd | B5: 1484993 | C5: 1456740 | D5: 1449269 | E5: 1479141 | F5: 1586130 | G5: 1649168 | H5: 1693022 | I5: 1854706 | J5: 1865676 | K5: 1292028 | L5: 1413506 | M5: 1534052 | N5: 1555810 | O5: 1529226 | P5: 21843467 | U5: tijdelijk | V5: =B5/1000 -> 1484.993 | W5: =C5/1000 -> 1456.74 | X5: =D5/1000 -> 1449.269 | Y5: =E5/1000 -> 1479.141 | Z5: =F5/1000 -> 1586.13 | AA5: =G5/1000 -> 1649.168 | AB5: =H5/1000 -> 1693.022 | AC5: =I5/1000 -> 1854.706 | ... AI5: =O5/1000 -> 1529.226
A6: Uitzend | B6: 335711 | C6: 332899 | D6: 331457 | E6: 354512 | F6: 395686 | G6: 427467 | H6: 470685 | I6: 596373 | J6: 547048 | K6: 414180 | L6: 513560 | M6: 514069 | N6: 460375 | O6: 436721 | P6: 6130743 | U6: uitzend | V6: =B6/1000 -> 335.711 | W6: =C6/1000 -> 332.899 | X6: =D6/1000 -> 331.457 | Y6: =E6/1000 -> 354.512 | Z6: =F6/1000 -> 395.686 | AA6: =G6/1000 -> 427.467 | AB6: =H6/1000 -> 470.685 | AC6: =I6/1000 -> 596.373 | ... AI6: =O6/1000 -> 436.721
A7: Oproep | B7: 391867 | C7: 438294 | D7: 451259 | E7: 480733 | F7: 480048 | G7: 493813 | H7: 556633 | I7: 545267 | J7: 571403 | K7: 838723 | L7: 892972 | M7: 911434 | N7: 912019 | O7: 909424 | P7: 8873889 | U7: oproep | V7: =B7/1000 -> 391.867 | W7: =C7/1000 -> 438.294 | X7: =D7/1000 -> 451.259 | Y7: =E7/1000 -> 480.733 | Z7: =F7/1000 -> 480.048 | AA7: =G7/1000 -> 493.813 | AB7: =H7/1000 -> 556.633 | AC7: =I7/1000 -> 545.267 | ... AI7: =O7/1000 -> 909.424
A9: Total | B9: 7092359 | C9: 7019072 | D9: 6908965 | E9: 6893544 | F9: 6953961 | G9: 7074535 | H9: 7255876 | I9: 7670437 | J9: 7765927 | K9: 7666065 | L9: 7938285 | M9: 8143837 | N9: 8219215 | O9: 8261791 | P9: 104863869 | U9: totaal | V9: =B9/1000 -> 7092.359 | W9: =C9/1000 -> 7019.072 | X9: =D9/1000 -> 6908.965 | Y9: =E9/1000 -> 6893.544 | Z9: =F9/1000 -> 6953.961 | AA9: =G9/1000 -> 7074.535 | AB9: =H9/1000 -> 7255.876 | AC9: =I9/1000 -> 7670.437 | ... AI9: =O9/1000 -> 8261.791
U10: totaal | V10: =#REF! -> #REF! | W10: =#REF! -> #REF! | X10: =#REF! -> #REF! | Y10: =#REF! -> #REF! | Z10: =#REF! -> #REF! | AA10: =#REF! -> #REF! | AB10: =#REF! -> #REF! | AC10: =#REF! -> #REF! | ... AI10: =#REF! -> #REF!
A11: switch_beid_stream==1 | B11: year
A12: Contract type | B12: 2011 | C12: 2012 | D12: 2013 | E12: 2014 | F12: 2015 | G12: 2016 | H12: 2017 | I12: 2018 | J12: 2019 | K12: 2020 | L12: 2021 | M12: 2022 | N12: 2023 | O12: 2024 | P12: Total | U12: Figuur
V13: 2011 | W13: 2012 | X13: 2013 | Y13: 2014 | Z13: 2015 | AA13: 2016 | AB13: 2017 | AC13: 2018 | AD13: 2019 | AE13: 2020 | AF13: 2021 | AG13: 2022 | AH13: 2023 | AI13: 2024
A14: Onbepaalde tijd | B14: 549714 | C14: 461335 | D14: 471467 | E14: 484428 | F14: 430169 | G14: 482886 | H14: 481777 | I14: 534554 | J14: 438533 | K14: 494504 | L14: 561042 | M14: 556869 | N14: 554413 | O14: 510425 | P14: 7012116 | U14: vast | V14: =B14/(V4*1000) -> 0.11265121 | W14: =C14/(W4*1000) -> 0.096289212 | X14: =D14/(X4*1000) -> 0.10080586 | Y14: =E14/(Y4*1000) -> 0.10578975 | Z14: =F14/(Z4*1000) -> 0.095761289 | AA14: =G14/(AA4*1000) -> 0.10721063 | AB14: =H14/(AB4*1000) -> 0.10622273 | AC14: =I14/(AC4*1000) -> 0.11436534 | ... AI14: =O14/(AI4*1000) -> 0.094761456
A15: Bepaalde tijd | B15: 335035 | C15: 309934 | D15: 324611 | E15: 352875 | F15: 402251 | G15: 434093 | H15: 446452 | I15: 475330 | J15: 422698 | K15: 325945 | L15: 374009 | M15: 380614 | N15: 376236 | O15: 358863 | P15: 5318946 | U15: tijdelijk | V15: =B15/(V5*1000) -> 0.22561386 | W15: =C15/(W5*1000) -> 0.21275863 | X15: =D15/(X5*1000) -> 0.22398257 | Y15: =E15/(Y5*1000) -> 0.23856752 | Z15: =F15/(Z5*1000) -> 0.25360532 | AA15: =G15/(AA5*1000) -> 0.26321939 | AB15: =H15/(AB5*1000) -> 0.26370124 | AC15: =I15/(AC5*1000) -> 0.25628321 | ... AI15: =O15/(AI5*1000) -> 0.2346697
A16: Uitzend | B16: 143069 | C16: 128941 | D16: 132331 | E16: 152521 | F16: 209215 | G16: 192444 | H16: 211690 | I16: 237066 | J16: 223968 | K16: 171571 | L16: 208985 | M16: 194249 | N16: 167980 | O16: 160816 | P16: 2534846 | U16: uitzend | V16: =B16/(V6*1000) -> 0.42616715 | W16: =C16/(W6*1000) -> 0.38732769 | X16: =D16/(X6*1000) -> 0.39924032 | Y16: =E16/(Y6*1000) -> 0.43022803 | Z16: =F16/(Z6*1000) -> 0.52873996 | AA16: =G16/(AA6*1000) -> 0.45019616 | AB16: =H16/(AB6*1000) -> 0.44974877 | AC16: =I16/(AC6*1000) -> 0.39751297 | ... AI16: =O16/(AI6*1000) -> 0.3682351
A17: Oproep | B17: 95120 | C17: 101440 | D17: 109183 | E17: 128141 | F17: 133909 | G17: 140594 | H17: 166056 | I17: 168053 | J17: 156139 | K17: 271489 | L17: 308896 | M17: 300835 | N17: 287535 | O17: 286371 | P17: 2653761 | U17: oproep | V17: =B17/(V7*1000) -> 0.24273542 | W17: =C17/(W7*1000) -> 0.23144282 | X17: =D17/(X7*1000) -> 0.24195196 | Y17: =E17/(Y7*1000) -> 0.26655337 | Z17: =F17/(Z7*1000) -> 0.27894919 | AA17: =G17/(AA7*1000) -> 0.28471101 | AB17: =H17/(AB7*1000) -> 0.29832223 | AC17: =I17/(AC7*1000) -> 0.30820314 | ... AI17: =O17/(AI7*1000) -> 0.31489272
A19: Total | B19: 1122938 | C19: 1001650 | D19: 1037592 | E19: 1117965 | F19: 1175544 | G19: 1250017 | H19: 1305975 | I19: 1415003 | J19: 1241338 | K19: 1263509 | L19: 1452932 | M19: 1432567 | N19: 1386164 | O19: 1316475 | P19: 17519669 | U19: totaal | V19: =B19/(V9*1000) -> 0.15833068 | W19: =C19/(W9*1000) -> 0.14270405 | X19: =D19/(X9*1000) -> 0.15018053 | Y19: =E19/(Y9*1000) -> 0.16217565 | Z19: =F19/(Z9*1000) -> 0.16904668 | AA19: =G19/(AA9*1000) -> 0.17669246 | AB19: =H19/(AB9*1000) -> 0.17998861 | AC19: =I19/(AC9*1000) -> 0.18447489 | ... AI19: =O19/(AI9*1000) -> 0.15934499
V20: =#REF! -> #REF! | W20: =#REF! -> #REF! | X20: =#REF! -> #REF! | Y20: =#REF! -> #REF! | Z20: =#REF! -> #REF! | AA20: =#REF! -> #REF! | AB20: =#REF! -> #REF! | AC20: =#REF! -> #REF! | ... AI20: =#REF! -> #REF!

Sheet Figuur_4e
A1: switch_beid_stream==0 | B1: year
A2: Number of hours worked per week | B2: 2011 | C2: 2012 | D2: 2013 | E2: 2014 | F2: 2015 | G2: 2016 | H2: 2017 | I2: 2018 | J2: 2019 | K2: 2020 | L2: 2021 | M2: 2022 | N2: 2023 | O2: 2024 | P2: Total | U2: TOTAAL WERKNEMERS
V3: 2011 | W3: 2012 | X3: 2013 | Y3: 2014 | Z3: 2015 | AA3: 2016 | AB3: 2017 | AC3: 2018 | AD3: 2019 | AE3: 2020 | AF3: 2021 | AG3: 2022 | AH3: 2023 | AI3: 2024
A4: <12 | B4: 844684 | C4: 866053 | D4: 882638 | E4: 881294 | F4: 888834 | G4: 831817 | H4: 843859 | I4: 865356 | J4: 877432 | K4: 824079 | L4: 796236 | M4: 831125 | N4: 825874 | O4: 854071 | P4: 11913352 | U4: minder dan 12 | V4: =B4/1000 -> 844.684 | W4: =C4/1000 -> 866.053 | X4: =D4/1000 -> 882.638 | Y4: =E4/1000 -> 881.294 | Z4: =F4/1000 -> 888.834 | AA4: =G4/1000 -> 831.817 | AB4: =H4/1000 -> 843.859 | AC4: =I4/1000 -> 865.356 | ... AI4: =O4/1000 -> 854.071
A5: 12-20 | B5: 768537 | C5: 793029 | D5: 725601 | E5: 710874 | F5: 693791 | G5: 721401 | H5: 685278 | I5: 694326 | J5: 684980 | K5: 663783 | L5: 683672 | M5: 677106 | N5: 663057 | O5: 648187 | P5: 9813622 | U5: 12-20 | V5: =B5/1000 -> 768.537 | W5: =C5/1000 -> 793.029 | X5: =D5/1000 -> 725.601 | Y5: =E5/1000 -> 710.874 | Z5: =F5/1000 -> 693.791 | AA5: =G5/1000 -> 721.401 | AB5: =H5/1000 -> 685.278 | AC5: =I5/1000 -> 694.326 | ... AI5: =O5/1000 -> 648.187
A6: 20-25 | B6: 755257 | C6: 746273 | D6: 737702 | E6: 725321 | F6: 738863 | G6: 770041 | H6: 831293 | I6: 858873 | J6: 880058 | K6: 881188 | L6: 903841 | M6: 912927 | N6: 919940 | O6: 921942 | P6: 11583519 | U6: 20-25 | V6: =B6/1000 -> 755.257 | W6: =C6/1000 -> 746.273 | X6: =D6/1000 -> 737.702 | Y6: =E6/1000 -> 725.321 | Z6: =F6/1000 -> 738.863 | AA6: =G6/1000 -> 770.041 | AB6: =H6/1000 -> 831.293 | AC6: =I6/1000 -> 858.873 | ... AI6: =O6/1000 -> 921.942
A7: 25-30 | B7: 478045 | C7: 582329 | D7: 521136 | E7: 544185 | F7: 552433 | G7: 574118 | H7: 602195 | I7: 647156 | J7: 663456 | K7: 663918 | L7: 696992 | M7: 719777 | N7: 729947 | O7: 732785 | P7: 8708472 | U7: 25-30 | V7: =B7/1000 -> 478.045 | W7: =C7/1000 -> 582.329 | X7: =D7/1000 -> 521.136 | Y7: =E7/1000 -> 544.185 | Z7: =F7/1000 -> 552.433 | AA7: =G7/1000 -> 574.118 | AB7: =H7/1000 -> 602.195 | AC7: =I7/1000 -> 647.156 | ... AI7: =O7/1000 -> 732.785
A8: 30-35 | B8: 813667 | C8: 851519 | D8: 753315 | E8: 777539 | F8: 788436 | G8: 826906 | H8: 859966 | I8: 924283 | J8: 967295 | K8: 973016 | L8: 1035830 | M8: 1084261 | N8: 1124957 | O8: 1162240 | P8: 12943230 | U8: 30-35 | V8: =B8/1000 -> 813.667 | W8: =C8/1000 -> 851.519 | X8: =D8/1000 -> 753.315 | Y8: =E8/1000 -> 777.539 | Z8: =F8/1000 -> 788.436 | AA8: =G8/1000 -> 826.906 | AB8: =H8/1000 -> 859.966 | AC8: =I8/1000 -> 924.283 | ... AI8: =O8/1000 -> 1162.24
A9: >=35 | B9: 3432169 | C9: 3179869 | D9: 3288573 | E9: 3254331 | F9: 3291604 | G9: 3350252 | H9: 3433285 | I9: 3680443 | J9: 3692706 | K9: 3660081 | L9: 3821714 | M9: 3918641 | N9: 3955440 | O9: 3942566 | P9: 49901674 | U9: 35 of meer | V9: =B9/1000 -> 3432.169 | W9: =C9/1000 -> 3179.869 | X9: =D9/1000 -> 3288.573 | Y9: =E9/1000 -> 3254.331 | Z9: =F9/1000 -> 3291.604 | AA9: =G9/1000 -> 3350.252 | AB9: =H9/1000 -> 3433.285 | AC9: =I9/1000 -> 3680.443 | ... AI9: =O9/1000 -> 3942.566
A11: Total | B11: 7092359 | C11: 7019072 | D11: 6908965 | E11: 6893544 | F11: 6953961 | G11: 7074535 | H11: 7255876 | I11: 7670437 | J11: 7765927 | K11: 7666065 | L11: 7938285 | M11: 8143837 | N11: 8219215 | O11: 8261791 | P11: 104863869 | U11: Total | V11: =B11/1000 -> 7092.359 | W11: =C11/1000 -> 7019.072 | X11: =D11/1000 -> 6908.965 | Y11: =E11/1000 -> 6893.544 | Z11: =F11/1000 -> 6953.961 | AA11: =G11/1000 -> 7074.535 | AB11: =H11/1000 -> 7255.876 | AC11: =I11/1000 -> 7670.437 | ... AI11: =O11/1000 -> 8261.791
V12: =#REF! -> #REF! | W12: =#REF! -> #REF! | X12: =#REF! -> #REF! | Y12: =#REF! -> #REF! | Z12: =#REF! -> #REF! | AA12: =#REF! -> #REF! | AB12: =#REF! -> #REF! | AC12: =#REF! -> #REF! | ... AI12: =#REF! -> #REF!
A13: switch_beid_stream==1 | B13: year
A14: Number of hours worked per week | B14: 2011 | C14: 2012 | D14: 2013 | E14: 2014 | F14: 2015 | G14: 2016 | H14: 2017 | I14: 2018 | J14: 2019 | K14: 2020 | L14: 2021 | M14: 2022 | N14: 2023 | O14: 2024 | P14: Total | U14: Figuur
V15: 2011 | W15: 2012 | X15: 2013 | Y15: 2014 | Z15: 2015 | AA15: 2016 | AB15: 2017 | AC15: 2018 | AD15: 2019 | AE15: 2020 | AF15: 2021 | AG15: 2022 | AH15: 2023 | AI15: 2024
A16: <12 | B16: 217664 | C16: 212938 | D16: 216650 | E16: 241582 | F16: 263542 | G16: 248201 | H16: 255753 | I16: 257471 | J16: 241478 | K16: 244837 | L16: 252439 | M16: 252225 | N16: 245129 | O16: 250600 | P16: 3400509 | U16: minder dan 12 uur | V16: =B16/(V4*1000) -> 0.2576869 | W16: =C16/(W4*1000) -> 0.24587179 | X16: =D16/(X4*1000) -> 0.24545737 | Y16: =E16/(Y4*1000) -> 0.27412192 | Z16: =F16/(Z4*1000) -> 0.29650306 | AA16: =G16/(AA4*1000) -> 0.29838414 | AB16: =H16/(AB4*1000) -> 0.30307551 | AC16: =I16/(AC4*1000) -> 0.29753188 | ... AI16: =O16/(AI4*1000) -> 0.29341823
A17: 12-20 | B17: 133799 | C17: 126848 | D17: 120417 | E17: 135092 | F17: 141967 | G17: 149826 | H17: 150745 | I17: 153962 | J17: 136706 | K17: 138638 | L17: 159888 | M17: 151551 | N17: 148532 | O17: 133800 | P17: 1981771 | U17: 12 tot 20 uur | V17: =B17/(V5*1000) -> 0.17409572 | W17: =C17/(W5*1000) -> 0.1599538 | X17: =D17/(X5*1000) -> 0.16595484 | Y17: =E17/(Y5*1000) -> 0.19003649 | Z17: =F17/(Z5*1000) -> 0.20462502 | AA17: =G17/(AA5*1000) -> 0.20768754 | AB17: =H17/(AB5*1000) -> 0.21997642 | AC17: =I17/(AC5*1000) -> 0.2217431 | ... AI17: =O17/(AI5*1000) -> 0.20642191
A18: 20-25 | B18: 106120 | C18: 89420 | D18: 91869 | E18: 107876 | F18: 109825 | G18: 120323 | H18: 131267 | I18: 139623 | J18: 122741 | K18: 126685 | L18: 148715 | M18: 144850 | N18: 145661 | O18: 126880 | P18: 1711855 | U18: 20 tot 25 uur | V18: =B18/(V6*1000) -> 0.14050846 | W18: =C18/(W6*1000) -> 0.1198221 | X18: =D18/(X6*1000) -> 0.12453403 | Y18: =E18/(Y6*1000) -> 0.14872863 | Z18: =F18/(Z6*1000) -> 0.14864055 | AA18: =G18/(AA6*1000) -> 0.15625532 | AB18: =H18/(AB6*1000) -> 0.15790702 | AC18: =I18/(AC6*1000) -> 0.16256536 | ... AI18: =O18/(AI6*1000) -> 0.13762254
A19: 25-30 | B19: 70404 | C19: 75003 | D19: 68244 | E19: 81233 | F19: 85646 | G19: 92186 | H19: 98681 | I19: 108253 | J19: 96009 | K19: 95640 | L19: 115511 | M19: 115064 | N19: 114626 | O19: 100996 | P19: 1317496 | U19: 25 tot 30 uur | V19: =B19/(V7*1000) -> 0.14727484 | W19: =C19/(W7*1000) -> 0.12879833 | X19: =D19/(X7*1000) -> 0.13095238 | Y19: =E19/(Y7*1000) -> 0.1492746 | Z19: =F19/(Z7*1000) -> 0.15503419 | AA19: =G19/(AA7*1000) -> 0.16056978 | AB19: =H19/(AB7*1000) -> 0.16386885 | AC19: =I19/(AC7*1000) -> 0.16727497 | ... AI19: =O19/(AI7*1000) -> 0.13782487
A20: 30-35 | B20: 118740 | C20: 102890 | D20: 101941 | E20: 117863 | F20: 122740 | G20: 135367 | H20: 143806 | I20: 160300 | J20: 145086 | K20: 145628 | L20: 176733 | M20: 181680 | N20: 177805 | O20: 166014 | P20: 1996593 | U20: 30 tot 35 uur | V20: =B20/(V8*1000) -> 0.14593194 | W20: =C20/(W8*1000) -> 0.12083113 | X20: =D20/(X8*1000) -> 0.1353232 | Y20: =E20/(Y8*1000) -> 0.15158468 | Z20: =F20/(Z8*1000) -> 0.15567529 | AA20: =G20/(AA8*1000) -> 0.16370301 | AB20: =H20/(AB8*1000) -> 0.16722289 | AC20: =I20/(AC8*1000) -> 0.17343173 | ... AI20: =O20/(AI8*1000) -> 0.14283969
A21: >=35 | B21: 476211 | C21: 394551 | D21: 438471 | E21: 434319 | F21: 451824 | G21: 504114 | H21: 525723 | I21: 595394 | J21: 499318 | K21: 512081 | L21: 599646 | M21: 587197 | N21: 554411 | O21: 538185 | P21: 7111445 | U21: 35 uur of meer | V21: =B21/(V9*1000) -> 0.13874929 | W21: =C21/(W9*1000) -> 0.12407775 | X21: =D21/(X9*1000) -> 0.13333169 | Y21: =E21/(Y9*1000) -> 0.13345877 | Z21: =F21/(Z9*1000) -> 0.1372656 | AA21: =G21/(AA9*1000) -> 0.15047047 | AB21: =H21/(AB9*1000) -> 0.15312536 | AC21: =I21/(AC9*1000) -> 0.16177237 | ... AI21: =O21/(AI9*1000) -> 0.13650628
A23: Total | B23: 1122938 | C23: 1001650 | D23: 1037592 | E23: 1117965 | F23: 1175544 | G23: 1250017 | H23: 1305975 | I23: 1415003 | J23: 1241338 | K23: 1263509 | L23: 1452932 | M23: 1432567 | N23: 1386164 | O23: 1316475 | P23: 17519669 | U23: Total | V23: =B23/(V11*1000) -> 0.15833068 | W23: =C23/(W11*1000) -> 0.14270405 | X23: =D23/(X11*1000) -> 0.15018053 | Y23: =E23/(Y11*1000) -> 0.16217565 | Z23: =F23/(Z11*1000) -> 0.16904668 | AA23: =G23/(AA11*1000) -> 0.17669246 | AB23: =H23/(AB11*1000) -> 0.17998861 | AC23: =I23/(AC11*1000) -> 0.18447489 | ... AI23: =O23/(AI11*1000) -> 0.15934499
V24: =#REF! -> #REF! | W24: =#REF! -> #REF! | X24: =#REF! -> #REF! | Y24: =#REF! -> #REF! | Z24: =#REF! -> #REF! | AA24: =#REF! -> #REF! | AB24: =#REF! -> #REF! | AC24: =#REF! -> #REF! | ... AI24: =#REF! -> #REF!

Sheet Figuur_4f
A1: switch_beid_stream==0 | B1: year
A2: Company size | B2: 2011 | C2: 2012 | D2: 2013 | E2: 2014 | F2: 2015 | G2: 2016 | H2: 2017 | I2: 2018 | J2: 2019 | K2: 2020 | L2: 2021 | M2: 2022 | N2: 2023 | O2: 2024 | P2: Total | U2: TOTAAL WERKNEMERS
V3: 2011 | W3: 2012 | X3: 2013 | Y3: 2014 | Z3: 2015 | AA3: 2016 | AB3: 2017 | AC3: 2018 | AD3: 2019 | AE3: 2020 | AF3: 2021 | AG3: 2022 | AH3: 2023 | AI3: 2024
A4: Micro: <10 employees | B4: 892433 | C4: 869972 | D4: 856478 | E4: 873846 | F4: 877171 | G4: 900375 | H4: 919410 | I4: 928780 | J4: 927935 | K4: 902985 | L4: 951206 | M4: 936946 | N4: 915863 | O4: 910298 | P4: 12663698 | U4: Micro: minder dan 10 werkenden | V4: =B4/1000 -> 892.433 | W4: =C4/1000 -> 869.972 | X4: =D4/1000 -> 856.478 | Y4: =E4/1000 -> 873.846 | Z4: =F4/1000 -> 877.171 | AA4: =G4/1000 -> 900.375 | AB4: =H4/1000 -> 919.41 | AC4: =I4/1000 -> 928.78 | ... AI4: =O4/1000 -> 910.298
A5: Small: 10-50 employees | B5: 1209556 | C5: 1178127 | D5: 1141457 | E5: 1140283 | F5: 1155287 | G5: 1182669 | H5: 1223660 | I5: 1282490 | J5: 1293092 | K5: 1280223 | L5: 1318414 | M5: 1374084 | N5: 1362196 | O5: 1350701 | P5: 17492239 | U5: Klein: 10 tot 50 werkenden | V5: =B5/1000 -> 1209.556 | W5: =C5/1000 -> 1178.127 | X5: =D5/1000 -> 1141.457 | Y5: =E5/1000 -> 1140.283 | Z5: =F5/1000 -> 1155.287 | AA5: =G5/1000 -> 1182.669 | AB5: =H5/1000 -> 1223.66 | AC5: =I5/1000 -> 1282.49 | ... AI5: =O5/1000 -> 1350.701
A6: Medium: 50-250 employees | B6: 1356077 | C6: 1329641 | D6: 1292930 | E6: 1286057 | F6: 1309938 | G6: 1338219 | H6: 1377875 | I6: 1454576 | J6: 1476121 | K6: 1445256 | L6: 1492264 | M6: 1512389 | N6: 1506557 | O6: 1499154 | P6: 19677054 | U6: Middel: 50 tot 250 werkenden | V6: =B6/1000 -> 1356.077 | W6: =C6/1000 -> 1329.641 | X6: =D6/1000 -> 1292.93 | Y6: =E6/1000 -> 1286.057 | Z6: =F6/1000 -> 1309.938 | AA6: =G6/1000 -> 1338.219 | AB6: =H6/1000 -> 1377.875 | AC6: =I6/1000 -> 1454.576 | ... AI6: =O6/1000 -> 1499.154
A7: Large: >250 employees | B7: 3634293 | C7: 3641332 | D7: 3618100 | E7: 3593358 | F7: 3611565 | G7: 3653272 | H7: 3734931 | I7: 4004591 | J7: 4068779 | K7: 4037601 | L7: 4176401 | M7: 4320418 | N7: 4434599 | O7: 4501638 | P7: 55030878 | U7: Groot: 250 werkenden of meer | V7: =B7/1000 -> 3634.293 | W7: =C7/1000 -> 3641.332 | X7: =D7/1000 -> 3618.1 | Y7: =E7/1000 -> 3593.358 | Z7: =F7/1000 -> 3611.565 | AA7: =G7/1000 -> 3653.272 | AB7: =H7/1000 -> 3734.931 | AC7: =I7/1000 -> 4004.591 | ... AI7: =O7/1000 -> 4501.638
A8: Total
B9: 7092359 | C9: 7019072 | D9: 6908965 | E9: 6893544 | F9: 6953961 | G9: 7074535 | H9: 7255876 | I9: 7670437 | J9: 7765927 | K9: 7666065 | L9: 7938285 | M9: 8143837 | N9: 8219215 | O9: 8261791 | P9: 104863869 | U9: totaal | V9: =B9/1000 -> 7092.359 | W9: =C9/1000 -> 7019.072 | X9: =D9/1000 -> 6908.965 | Y9: =E9/1000 -> 6893.544 | Z9: =F9/1000 -> 6953.961 | AA9: =G9/1000 -> 7074.535 | AB9: =H9/1000 -> 7255.876 | AC9: =I9/1000 -> 7670.437 | ... AI9: =O9/1000 -> 8261.791
A10: switch_beid_stream==1 | B10: year | V10: =#REF! -> #REF! | W10: =#REF! -> #REF! | X10: =#REF! -> #REF! | Y10: =#REF! -> #REF! | Z10: =#REF! -> #REF! | AA10: =#REF! -> #REF! | AB10: =#REF! -> #REF! | AC10: =#REF! -> #REF! | ... AI10: =#REF! -> #REF!
A11: Company size | B11: 2011 | C11: 2012 | D11: 2013 | E11: 2014 | F11: 2015 | G11: 2016 | H11: 2017 | I11: 2018 | J11: 2019 | K11: 2020 | L11: 2021 | M11: 2022 | N11: 2023 | O11: 2024 | P11: Total
U12: Figuur
A13: Micro: <10 employees | B13: 159494 | C13: 154592 | D13: 161718 | E13: 162318 | F13: 170123 | G13: 183812 | H13: 197520 | I13: 206799 | J13: 176981 | K13: 179732 | L13: 209346 | M13: 193462 | N13: 180318 | O13: 178386 | P13: 2514601 | V13: 2011 | W13: 2012 | X13: 2013 | Y13: 2014 | Z13: 2015 | AA13: 2016 | AB13: 2017 | AC13: 2018 | AD13: 2019 | AE13: 2020 | AF13: 2021 | AG13: 2022 | AH13: 2023 | AI13: 2024
A14: Small: 10-50 employees | B14: 201081 | C14: 186004 | D14: 186992 | E14: 195449 | F14: 206884 | G14: 221484 | H14: 240837 | I14: 254582 | J14: 220717 | K14: 238826 | L14: 270785 | M14: 276782 | N14: 258115 | O14: 253646 | P14: 3212184 | U14: Micro: <10 werkenden | V14: =B13/(V4*1000) -> 0.17871818 | W14: =C13/(W4*1000) -> 0.17769767 | X14: =D13/(X4*1000) -> 0.18881746 | Y14: =E13/(Y4*1000) -> 0.18575127 | Z14: =F13/(Z4*1000) -> 0.19394508 | AA14: =G13/(AA4*1000) -> 0.20415049 | AB14: =H13/(AB4*1000) -> 0.21483343 | AC14: =I13/(AC4*1000) -> 0.2226566 | ... AI14: =O13/(AI4*1000) -> 0.1959644
A15: Medium: 50-250 employees | B15: 209999 | C15: 187350 | D15: 188246 | E15: 193306 | F15: 213064 | G15: 226226 | H15: 245168 | I15: 258239 | J15: 231427 | K15: 236987 | L15: 285258 | M15: 274917 | N15: 253014 | O15: 247641 | P15: 3250842 | U15: Klein: 10-49 werkenden | V15: =B14/(V5*1000) -> 0.16624365 | W15: =C14/(W5*1000) -> 0.15788111 | X15: =D14/(X5*1000) -> 0.1638187 | Y15: =E14/(Y5*1000) -> 0.17140394 | Z15: =F14/(Z5*1000) -> 0.17907585 | AA15: =G14/(AA5*1000) -> 0.18727472 | AB15: =H14/(AB5*1000) -> 0.19681693 | AC15: =I14/(AC5*1000) -> 0.19850603 | ... AI15: =O14/(AI5*1000) -> 0.18778842
A16: Large: >250 employees | B16: 552364 | C16: 473704 | D16: 500636 | E16: 566892 | F16: 585473 | G16: 618495 | H16: 622450 | I16: 695383 | J16: 612213 | K16: 607964 | L16: 687543 | M16: 687406 | N16: 694717 | O16: 636802 | P16: 8542042 | U16: Middel: 50-249 werkenden | V16: =B15/(V6*1000) -> 0.15485773 | W16: =C15/(W6*1000) -> 0.14090269 | X16: =D15/(X6*1000) -> 0.14559644 | Y16: =E15/(Y6*1000) -> 0.15030905 | Z16: =F15/(Z6*1000) -> 0.16265197 | AA16: =G15/(AA6*1000) -> 0.16905006 | AB16: =H15/(AB6*1000) -> 0.17793196 | AC16: =I15/(AC6*1000) -> 0.17753558 | ... AI16: =O15/(AI6*1000) -> 0.16518717
A17: Total | U17: Groot: >=250 werkenden | V17: =B16/(V7*1000) -> 0.15198664 | W17: =C16/(W7*1000) -> 0.13009086 | X17: =D16/(X7*1000) -> 0.13836986 | Y17: =E16/(Y7*1000) -> 0.15776107 | Z17: =F16/(Z7*1000) -> 0.16211061 | AA17: =G16/(AA7*1000) -> 0.16929892 | AB17: =H16/(AB7*1000) -> 0.16665636 | AC17: =I16/(AC7*1000) -> 0.17364645 | ... AI17: =O16/(AI7*1000) -> 0.14146006
B18: 1122938 | C18: 1001650 | D18: 1037592 | E18: 1117965 | F18: 1175544 | G18: 1250017 | H18: 1305975 | I18: 1415003 | J18: 1241338 | K18: 1263509 | L18: 1452932 | M18: 1432567 | N18: 1386164 | O18: 1316475 | P18: 17519669
U19: totaal | V19: =B18/(V9*1000) -> 0.15833068 | W19: =C18/(W9*1000) -> 0.14270405 | X19: =D18/(X9*1000) -> 0.15018053 | Y19: =E18/(Y9*1000) -> 0.16217565 | Z19: =F18/(Z9*1000) -> 0.16904668 | AA19: =G18/(AA9*1000) -> 0.17669246 | AB19: =H18/(AB9*1000) -> 0.17998861 | AC19: =I18/(AC9*1000) -> 0.18447489 | ... AI19: =O18/(AI9*1000) -> 0.15934499
V20: =#REF! -> #REF! | W20: =#REF! -> #REF! | X20: =#REF! -> #REF! | Y20: =#REF! -> #REF! | Z20: =#REF! -> #REF! | AA20: =#REF! -> #REF! | AB20: =#REF! -> #REF! | AC20: =#REF! -> #REF! | ... AI20: =#REF! -> #REF!

Sheet Figuur_5
A1: alle werkenden: table sbi year if hoofdbaan==1., format(%12.0f) row col nol
AI2: Baanstarters (ref =2025)
B3: 2011 | C3: 2012 | D3: 2013 | E3: 2014 | F3: 2015 | G3: 2016 | H3: 2017 | I3: 2018 | J3: 2019 | K3: 2020 | L3: 2021 | M3: 2022 | N3: 2023 | O3: 2024 | P3: Total | S3: TBV FIGUUR: TOTAAL WERKNEMERS | AK3: baan-baanwisselaars | AL3: instromers | AM3: totaal werkenden 2025 | AP3: baanstarters | baan-baanwisselaars | AQ3: baanstarters | instromers | AR3: totaal werkenden 2025
T4: 2011 | U4: 2012 | V4: 2013 | W4: 2014 | X4: 2015 | Y4: 2016 | Z4: 2017 | AA4: 2018 | AB4: 2019 | AC4: 2020 | AD4: 2021 | AE4: 2022 | AF4: 2023 | AG4: 2024 | AJ4: A Agrarisch | AK4: =('T_B.3.1'!V8-'T_B.3.1'!U8)/1000 -> 13.717 | AL4: ='T_B.3.1'!U8/1000 -> 11.256 | AM4: =AG86 -> 96.36 | AO4: A Agrarisch | AP4: =AK4/AM4 -> 0.1423516 | AQ4: =AL4/AM4 -> 0.11681196
A5: Landbouw, bosbouw en visserij | B5: 84163 | C5: 83153 | D5: 83870 | E5: 83197 | F5: 82620 | G5: 83076 | H5: 83338 | I5: 104881 | J5: 100819 | K5: 99354 | L5: 107324 | M5: 103978 | N5: 102587 | O5: 102447 | P5: 1304807 | S5: A Agrarisch | T5: =B5/1000 -> 84.163 | U5: =C5/1000 -> 83.153 | V5: =D5/1000 -> 83.87 | W5: =E5/1000 -> 83.197 | X5: =F5/1000 -> 82.62 | Y5: =G5/1000 -> 83.076 | Z5: =H5/1000 -> 83.338 | AA5: =I5/1000 -> 104.881 | ... AG5: =O5/1000 -> 102.447 | AJ5: C* Industrie | AK5: =('T_B.3.1'!V9-'T_B.3.1'!U9)/1000 -> 87.112 | AL5: ='T_B.3.1'!U9/1000 -> 29.84 | AM5: =AG87 -> 724.955 | AO5: C* Industrie | AP5: =AK5/AM5 -> 0.12016194 | AQ5: =AL5/AM5 -> 0.041161176
A6: Winning van delfstoffen | B6: 7980 | C6: 8058 | D6: 9814 | E6: 10300 | F6: 10197 | G6: 9662 | H6: 7925 | I6: 8055 | J6: 8114 | K6: 8069 | L6: 7406 | M6: 7676 | N6: 7972 | O6: 8001 | P6: 119229 | S6: C* Industrie | T6: =(B6+B7)/1000 -> 642.955 | U6: =(C6+C7)/1000 -> 631.503 | V6: =(D6+D7)/1000 -> 619.555 | W6: =(E6+E7)/1000 -> 616.528 | X6: =(F6+F7)/1000 -> 618.417 | Y6: =(G6+G7)/1000 -> 626.022 | Z6: =(H6+H7)/1000 -> 637.979 | AA6: =(I6+I7)/1000 -> 667.956 | ... AG6: =(O6+O7)/1000 -> 726.723 | AJ6: D** Energie | AK6: =('T_B.3.1'!V10-'T_B.3.1'!U10)/1000 -> 12.149 | AL6: ='T_B.3.1'!U10/1000 -> 3.059 | AM6: =AG88 -> 81.022 | AO6: D** Energie | AP6: =AK6/AM6 -> 0.14994693 | AQ6: =AL6/AM6 -> 0.037755178
A7: Industrie | B7: 634975 | C7: 623445 | D7: 609741 | E7: 606228 | F7: 608220 | G7: 616360 | H7: 630054 | I7: 659901 | J7: 677933 | K7: 671285 | L7: 680189 | M7: 699620 | N7: 715522 | O7: 718722 | P7: 9152195 | S7: D** Energie | T7: =(B8+B9)/1000 -> 59.818 | U7: =(C8+C9)/1000 -> 62.555 | V7: =(D8+D9)/1000 -> 56.959 | W7: =(E8+E9)/1000 -> 57.019 | X7: =(F8+F9)/1000 -> 57.876 | Y7: =(G8+G9)/1000 -> 57.729 | Z7: =(H8+H9)/1000 -> 58.724 | AA7: =(I8+I9)/1000 -> 60.719 | ... AG7: =(O8+O9)/1000 -> 77.283 | AJ7: F Bouwnijverheid | AK7: =('T_B.3.1'!V11-'T_B.3.1'!U11)/1000 -> 52.917 | AL7: ='T_B.3.1'!U11/1000 -> 20.2 | AM7: =AG89 -> 344.432 | AO7: F Bouwnijverheid | AP7: =AK7/AM7 -> 0.15363555 | AQ7: =AL7/AM7 -> 0.05864728
A8: Productie en distributie van en handel in elektriciteit, aardgas, stoom en gekoelde lucht | B8: 23135 | C8: 26131 | D8: 25628 | E8: 25480 | F8: 26632 | G8: 25999 | H8: 26078 | I8: 26482 | J8: 26771 | K8: 27825 | L8: 29691 | M8: 31646 | N8: 34152 | O8: 38720 | P8: 394370 | S8: F Bouwnijverheid | T8: =B10/1000 -> 341.145 | U8: =C10/1000 -> 322.806 | V8: =D10/1000 -> 294.204 | W8: =E10/1000 -> 279.94 | X8: =F10/1000 -> 273.999 | Y8: =G10/1000 -> 275.756 | Z8: =H10/1000 -> 284.512 | AA8: =I10/1000 -> 298.621 | ... AG8: =O10/1000 -> 333.128 | AJ8: G Handel | AK8: =('T_B.3.1'!V12-'T_B.3.1'!U12)/1000 -> 200.29 | AL8: ='T_B.3.1'!U12/1000 -> 134.249 | AM8: =AG90 -> 1294.115 | AO8: G Handel | AP8: =AK8/AM8 -> 0.15476986 | AQ8: =AL8/AM8 -> 0.10373808
A9: Winning en distributie van water; afval- en afvalwaterbeheer en sanering | B9: 36683 | C9: 36424 | D9: 31331 | E9: 31539 | F9: 31244 | G9: 31730 | H9: 32646 | I9: 34237 | J9: 34779 | K9: 35211 | L9: 36132 | M9: 37105 | N9: 37842 | O9: 38563 | P9: 485466 | S9: G Handel | T9: =B11/1000 -> 1215.519 | U9: =C11/1000 -> 1211.387 | V9: =D11/1000 -> 1196.307 | W9: =E11/1000 -> 1197.166 | X9: =F11/1000 -> 1216.343 | Y9: =G11/1000 -> 1229.738 | Z9: =H11/1000 -> 1265.707 | AA9: =I11/1000 -> 1307.023 | ... AG9: =O11/1000 -> 1359.114 | AJ9: H Vervoer & Logistiek | AK9: =('T_B.3.1'!V13-'T_B.3.1'!U13)/1000 -> 57.062 | AL9: ='T_B.3.1'!U13/1000 -> 23.821 | AM9: =AG91 -> 391.22 | AO9: H Vervoer & Logistiek | AP9: =AK9/AM9 -> 0.14585655 | AQ9: =AL9/AM9 -> 0.060889014
A10: Bouwnijverheid | B10: 341145 | C10: 322806 | D10: 294204 | E10: 279940 | F10: 273999 | G10: 275756 | H10: 284512 | I10: 298621 | J10: 307885 | K10: 312121 | L10: 319060 | M10: 326825 | N10: 331314 | O10: 333128 | P10: 4301316 | S10: H Vervoer & Logistiek | T10: =B12/1000 -> 352.575 | U10: =C12/1000 -> 348.287 | V10: =D12/1000 -> 343.04 | W10: =E12/1000 -> 338.859 | X10: =F12/1000 -> 337.8 | Y10: =G12/1000 -> 339.908 | Z10: =H12/1000 -> 345.198 | AA10: =I12/1000 -> 368.205 | ... AG10: =O12/1000 -> 386.862 | AJ10: I Horeca | AK10: =('T_B.3.1'!V14-'T_B.3.1'!U14)/1000 -> 111.282 | AL10: ='T_B.3.1'!U14/1000 -> 78.692 | AM10: =AG92 -> 426.368 | AO10: I Horeca | AP10: =AK10/AM10 -> 0.26099989 | AQ10: =AL10/AM10 -> 0.18456357
A11: Groot- en detailhandel; reparatie van auto's | B11: 1215519 | C11: 1211387 | D11: 1196307 | E11: 1197166 | F11: 1216343 | G11: 1229738 | H11: 1265707 | I11: 1307023 | J11: 1320662 | K11: 1325607 | L11: 1339123 | M11: 1354859 | N11: 1354643 | O11: 1359114 | P11: 17893198 | S11: I Horeca | T11: =B13/1000 -> 303.527 | U11: =C13/1000 -> 308.716 | V11: =D13/1000 -> 311.683 | W11: =E13/1000 -> 323.327 | X11: =F13/1000 -> 337.807 | Y11: =G13/1000 -> 356.651 | Z11: =H13/1000 -> 371.767 | AA11: =I13/1000 -> 389.177 | ... AG11: =O13/1000 -> 446.855 | AJ11: J Media & ICT | AK11: =('T_B.3.1'!V15-'T_B.3.1'!U15)/1000 -> 43.301 | AL11: ='T_B.3.1'!U15/1000 -> 19.588 | AM11: =AG93 -> 296.17 | AO11: J Media & ICT | AP11: =AK11/AM11 -> 0.14620319 | AQ11: =AL11/AM11 -> 0.066137691
A12: Vervoer en opslag | B12: 352575 | C12: 348287 | D12: 343040 | E12: 338859 | F12: 337800 | G12: 339908 | H12: 345198 | I12: 368205 | J12: 372972 | K12: 366371 | L12: 372961 | M12: 381304 | N12: 385277 | O12: 386862 | P12: 5039619 | S12: J Media & ICT | T12: =B14/1000 -> 212.013 | U12: =C14/1000 -> 213.073 | V12: =D14/1000 -> 207.814 | W12: =E14/1000 -> 214.61 | X12: =F14/1000 -> 220.336 | Y12: =G14/1000 -> 230.434 | Z12: =H14/1000 -> 242.823 | AA12: =I14/1000 -> 254.013 | ... AG12: =O14/1000 -> 300.255 | AJ12: K Financieel | AK12: =('T_B.3.1'!V16-'T_B.3.1'!U16)/1000 -> 42.058 | AL12: ='T_B.3.1'!U16/1000 -> 7.541 | AM12: =AG94 -> 211.97 | AO12: K Financieel | AP12: =AK12/AM12 -> 0.19841487 | AQ12: =AL12/AM12 -> 0.035575789
A13: Logies-, maaltijd- en drankverstrekking | B13: 303527 | C13: 308716 | D13: 311683 | E13: 323327 | F13: 337807 | G13: 356651 | H13: 371767 | I13: 389177 | J13: 401409 | K13: 380253 | L13: 391462 | M13: 421840 | N13: 442320 | O13: 446855 | P13: 5186794 | S13: K Financieel | T13: =B15/1000 -> 234.418 | U13: =C15/1000 -> 228.655 | V13: =D15/1000 -> 221.497 | W13: =E15/1000 -> 212.691 | X13: =F15/1000 -> 218.259 | Y13: =G15/1000 -> 212.601 | Z13: =H15/1000 -> 201.126 | AA13: =I15/1000 -> 198.83 | ... AG13: =O15/1000 -> 211.454 | AJ13: L Onroerend goed | AK13: =('T_B.3.1'!V17-'T_B.3.1'!U17)/1000 -> 11.09 | AL13: ='T_B.3.1'!U17/1000 -> 3.689 | AM13: =AG95 -> 65.604 | AO13: L Onroerend goed | AP13: =AK13/AM13 -> 0.16904457 | AQ13: =AL13/AM13 -> 0.056231327
A14: Informatie en communicatie | B14: 212013 | C14: 213073 | D14: 207814 | E14: 214610 | F14: 220336 | G14: 230434 | H14: 242823 | I14: 254013 | J14: 262813 | K14: 268397 | L14: 283308 | M14: 301173 | N14: 305508 | O14: 300255 | P14: 3516570 | S14: L Onroerend goed | T14: =B16/1000 -> 60.218 | U14: =C16/1000 -> 57.744 | V14: =D16/1000 -> 56.151 | W14: =E16/1000 -> 55.402 | X14: =F16/1000 -> 54.903 | Y14: =G16/1000 -> 55.452 | Z14: =H16/1000 -> 56.253 | AA14: =I16/1000 -> 56.824 | ... AG14: =O16/1000 -> 62.897 | AJ14: M Zakelijk | AK14: =('T_B.3.1'!V18-'T_B.3.1'!U18)/1000 -> 91.421 | AL14: ='T_B.3.1'!U18/1000 -> 37.242 | AM14: =AG96 -> 501.647 | AO14: M Zakelijk | AP14: =AK14/AM14 -> 0.1822417 | AQ14: =AL14/AM14 -> 0.074239455
